Workbook

Sheet Home
A1: DTIA Compliance Knowledge Base
A3: Countries | B3: 4
A4: Acts | B4: 37
A5: Regulators | B5: 43
A6: Topics | B6: 27
A7: Compliance sections | B7: 1368
A10: How to use
A11: 1. Open the Query sheet.
A12: 2. Pick a Country, Category, Topic, Data Type, Financial Relevance or Authority — or type a keyword.
A13: 3. Matching sections appear below, each with its Act and page reference for the source document.
A14: 4. The Data Transfer sheet answers cross-border questions: pick two countries and see every relevant act/section from either side of the transfer.
A15: 5. The Compliance Database sheet holds every extracted section; Acts / Regulators / Topics summarise them.

Sheet Query
A1: DTIA Query Engine
A3: Choose filters (leave as 'All' to ignore), then read the results below.
A4: Country | B4: All
A5: Topic | B5: All
A6: Data Type | B6: All
A7: Financial Relevance | B7: All
A8: Authority | B8: All
A9: Keyword (free text)
A12: Matching sections (of 1368 total): | C12: =Engine!$D$1
A13: Country | B13: Act | C13: Section | D13: Heading | E13: Pages | F13: Financial Relevance | G13: Confidence | H13: Topics | I13: Data Types | J13: Authority | K13: Summary | L13: DTIA Summary | M13: Requirements | N13: Source Quote | O13: Source
A14: =IF(ISNA(MATCH(1,Engine!$C$2:$C$1369,0)),"",INDEX('Compliance Database'!$A$2:$A$1369,MATCH(1,Engine!$C$2:$C$1369,0))) | B14: =IF(ISNA(MATCH(1,Engine!$C$2:$C$1369,0)),"",INDEX('Compliance Database'!$B$2:$B$1369,MATCH(1,Engine!$C$2:$C$1369,0))) | C14: =IF(ISNA(MATCH(1,Engine!$C$2:$C$1369,0)),"",INDEX('Compliance Database'!$C$2:$C$1369,MATCH(1,Engine!$C$2:$C$1369,0))) | D14: =IF(ISNA(MATCH(1,Engine!$C$2:$C$1369,0)),"",INDEX('Compliance Database'!$D$2:$D$1369,MATCH(1,Engine!$C$2:$C$1369,0))) | E14: =IF(ISNA(MATCH(1,Engine!$C$2:$C$1369,0)),"",INDEX('Compliance Database'!$E$2:$E$1369,MATCH(1,Engine!$C$2:$C$1369,0))) | F14: =IF(ISNA(MATCH(1,Engine!$C$2:$C$1369,0)),"",INDEX('Compliance Database'!$F$2:$F$1369,MATCH(1,Engine!$C$2:$C$1369,0))) | G14: =IF(ISNA(MATCH(1,Engine!$C$2:$C$1369,0)),"",INDEX('Compliance Database'!$G$2:$G$1369,MATCH(1,Engine!$C$2:$C$1369,0))) | H14: =IF(ISNA(MATCH(1,Engine!$C$2:$C$1369,0)),"",INDEX('Compliance Database'!$H$2:$H$1369,MATCH(1,Engine!$C$2:$C$1369,0))) | I14: =IF(ISNA(MATCH(1,Engine!$C$2:$C$1369,0)),"",INDEX('Compliance Database'!$I$2:$I$1369,MATCH(1,Engine!$C$2:$C$1369,0))) | J14: =IF(ISNA(MATCH(1,Engine!$C$2:$C$1369,0)),"",INDEX('Compliance Database'!$J$2:$J$1369,MATCH(1,Engine!$C$2:$C$1369,0))) | K14: =IF(ISNA(MATCH(1,Engine!$C$2:$C$1369,0)),"",INDEX('Compliance Database'!$K$2:$K$1369,MATCH(1,Engine!$C$2:$C$1369,0))) | L14: =IF(ISNA(MATCH(1,Engine!$C$2:$C$1369,0)),"",INDEX('Compliance Database'!$L$2:$L$1369,MATCH(1,Engine!$C$2:$C$1369,0))) | M14: =IF(ISNA(MATCH(1,Engine!$C$2:$C$1369,0)),"",INDEX('Compliance Database'!$M$2:$M$1369,MATCH(1,Engine!$C$2:$C$1369,0))) | N14: =IF(ISNA(MATCH(1,Engine!$C$2:$C$1369,0)),"",INDEX('Compliance Database'!$N$2:$N$1369,MATCH(1,Engine!$C$2:$C$1369,0))) | O14: =IF(ISNA(MATCH(1,Engine!$C$2:$C$1369,0)),"",HYPERLINK(INDEX('Compliance Database'!$O$2:$O$1369,MATCH(1,Engine!$C$2:$C$1369,0)),"Open PDF"))
A15: =IF(ISNA(MATCH(2,Engine!$C$2:$C$1369,0)),"",INDEX('Compliance Database'!$A$2:$A$1369,MATCH(2,Engine!$C$2:$C$1369,0))) | B15: =IF(ISNA(MATCH(2,Engine!$C$2:$C$1369,0)),"",INDEX('Compliance Database'!$B$2:$B$1369,MATCH(2,Engine!$C$2:$C$1369,0))) | C15: =IF(ISNA(MATCH(2,Engine!$C$2:$C$1369,0)),"",INDEX('Compliance Database'!$C$2:$C$1369,MATCH(2,Engine!$C$2:$C$1369,0))) | D15: =IF(ISNA(MATCH(2,Engine!$C$2:$C$1369,0)),"",INDEX('Compliance Database'!$D$2:$D$1369,MATCH(2,Engine!$C$2:$C$1369,0))) | E15: =IF(ISNA(MATCH(2,Engine!$C$2:$C$1369,0)),"",INDEX('Compliance Database'!$E$2:$E$1369,MATCH(2,Engine!$C$2:$C$1369,0))) | F15: =IF(ISNA(MATCH(2,Engine!$C$2:$C$1369,0)),"",INDEX('Compliance Database'!$F$2:$F$1369,MATCH(2,Engine!$C$2:$C$1369,0))) | G15: =IF(ISNA(MATCH(2,Engine!$C$2:$C$1369,0)),"",INDEX('Compliance Database'!$G$2:$G$1369,MATCH(2,Engine!$C$2:$C$1369,0))) | H15: =IF(ISNA(MATCH(2,Engine!$C$2:$C$1369,0)),"",INDEX('Compliance Database'!$H$2:$H$1369,MATCH(2,Engine!$C$2:$C$1369,0))) | I15: =IF(ISNA(MATCH(2,Engine!$C$2:$C$1369,0)),"",INDEX('Compliance Database'!$I$2:$I$1369,MATCH(2,Engine!$C$2:$C$1369,0))) | J15: =IF(ISNA(MATCH(2,Engine!$C$2:$C$1369,0)),"",INDEX('Compliance Database'!$J$2:$J$1369,MATCH(2,Engine!$C$2:$C$1369,0))) | K15: =IF(ISNA(MATCH(2,Engine!$C$2:$C$1369,0)),"",INDEX('Compliance Database'!$K$2:$K$1369,MATCH(2,Engine!$C$2:$C$1369,0))) | L15: =IF(ISNA(MATCH(2,Engine!$C$2:$C$1369,0)),"",INDEX('Compliance Database'!$L$2:$L$1369,MATCH(2,Engine!$C$2:$C$1369,0))) | M15: =IF(ISNA(MATCH(2,Engine!$C$2:$C$1369,0)),"",INDEX('Compliance Database'!$M$2:$M$1369,MATCH(2,Engine!$C$2:$C$1369,0))) | N15: =IF(ISNA(MATCH(2,Engine!$C$2:$C$1369,0)),"",INDEX('Compliance Database'!$N$2:$N$1369,MATCH(2,Engine!$C$2:$C$1369,0))) | O15: =IF(ISNA(MATCH(2,Engine!$C$2:$C$1369,0)),"",HYPERLINK(INDEX('Compliance Database'!$O$2:$O$1369,MATCH(2,Engine!$C$2:$C$1369,0)),"Open PDF"))
A16: =IF(ISNA(MATCH(3,Engine!$C$2:$C$1369,0)),"",INDEX('Compliance Database'!$A$2:$A$1369,MATCH(3,Engine!$C$2:$C$1369,0))) | B16: =IF(ISNA(MATCH(3,Engine!$C$2:$C$1369,0)),"",INDEX('Compliance Database'!$B$2:$B$1369,MATCH(3,Engine!$C$2:$C$1369,0))) | C16: =IF(ISNA(MATCH(3,Engine!$C$2:$C$1369,0)),"",INDEX('Compliance Database'!$C$2:$C$1369,MATCH(3,Engine!$C$2:$C$1369,0))) | D16: =IF(ISNA(MATCH(3,Engine!$C$2:$C$1369,0)),"",INDEX('Compliance Database'!$D$2:$D$1369,MATCH(3,Engine!$C$2:$C$1369,0))) | E16: =IF(ISNA(MATCH(3,Engine!$C$2:$C$1369,0)),"",INDEX('Compliance Database'!$E$2:$E$1369,MATCH(3,Engine!$C$2:$C$1369,0))) | F16: =IF(ISNA(MATCH(3,Engine!$C$2:$C$1369,0)),"",INDEX('Compliance Database'!$F$2:$F$1369,MATCH(3,Engine!$C$2:$C$1369,0))) | G16: =IF(ISNA(MATCH(3,Engine!$C$2:$C$1369,0)),"",INDEX('Compliance Database'!$G$2:$G$1369,MATCH(3,Engine!$C$2:$C$1369,0))) | H16: =IF(ISNA(MATCH(3,Engine!$C$2:$C$1369,0)),"",INDEX('Compliance Database'!$H$2:$H$1369,MATCH(3,Engine!$C$2:$C$1369,0))) | I16: =IF(ISNA(MATCH(3,Engine!$C$2:$C$1369,0)),"",INDEX('Compliance Database'!$I$2:$I$1369,MATCH(3,Engine!$C$2:$C$1369,0))) | J16: =IF(ISNA(MATCH(3,Engine!$C$2:$C$1369,0)),"",INDEX('Compliance Database'!$J$2:$J$1369,MATCH(3,Engine!$C$2:$C$1369,0))) | K16: =IF(ISNA(MATCH(3,Engine!$C$2:$C$1369,0)),"",INDEX('Compliance Database'!$K$2:$K$1369,MATCH(3,Engine!$C$2:$C$1369,0))) | L16: =IF(ISNA(MATCH(3,Engine!$C$2:$C$1369,0)),"",INDEX('Compliance Database'!$L$2:$L$1369,MATCH(3,Engine!$C$2:$C$1369,0))) | M16: =IF(ISNA(MATCH(3,Engine!$C$2:$C$1369,0)),"",INDEX('Compliance Database'!$M$2:$M$1369,MATCH(3,Engine!$C$2:$C$1369,0))) | N16: =IF(ISNA(MATCH(3,Engine!$C$2:$C$1369,0)),"",INDEX('Compliance Database'!$N$2:$N$1369,MATCH(3,Engine!$C$2:$C$1369,0))) | O16: =IF(ISNA(MATCH(3,Engine!$C$2:$C$1369,0)),"",HYPERLINK(INDEX('Compliance Database'!$O$2:$O$1369,MATCH(3,Engine!$C$2:$C$1369,0)),"Open PDF"))
A17: =IF(ISNA(MATCH(4,Engine!$C$2:$C$1369,0)),"",INDEX('Compliance Database'!$A$2:$A$1369,MATCH(4,Engine!$C$2:$C$1369,0))) | B17: =IF(ISNA(MATCH(4,Engine!$C$2:$C$1369,0)),"",INDEX('Compliance Database'!$B$2:$B$1369,MATCH(4,Engine!$C$2:$C$1369,0))) | C17: =IF(ISNA(MATCH(4,Engine!$C$2:$C$1369,0)),"",INDEX('Compliance Database'!$C$2:$C$1369,MATCH(4,Engine!$C$2:$C$1369,0))) | D17: =IF(ISNA(MATCH(4,Engine!$C$2:$C$1369,0)),"",INDEX('Compliance Database'!$D$2:$D$1369,MATCH(4,Engine!$C$2:$C$1369,0))) | E17: =IF(ISNA(MATCH(4,Engine!$C$2:$C$1369,0)),"",INDEX('Compliance Database'!$E$2:$E$1369,MATCH(4,Engine!$C$2:$C$1369,0))) | F17: =IF(ISNA(MATCH(4,Engine!$C$2:$C$1369,0)),"",INDEX('Compliance Database'!$F$2:$F$1369,MATCH(4,Engine!$C$2:$C$1369,0))) | G17: =IF(ISNA(MATCH(4,Engine!$C$2:$C$1369,0)),"",INDEX('Compliance Database'!$G$2:$G$1369,MATCH(4,Engine!$C$2:$C$1369,0))) | H17: =IF(ISNA(MATCH(4,Engine!$C$2:$C$1369,0)),"",INDEX('Compliance Database'!$H$2:$H$1369,MATCH(4,Engine!$C$2:$C$1369,0))) | I17: =IF(ISNA(MATCH(4,Engine!$C$2:$C$1369,0)),"",INDEX('Compliance Database'!$I$2:$I$1369,MATCH(4,Engine!$C$2:$C$1369,0))) | J17: =IF(ISNA(MATCH(4,Engine!$C$2:$C$1369,0)),"",INDEX('Compliance Database'!$J$2:$J$1369,MATCH(4,Engine!$C$2:$C$1369,0))) | K17: =IF(ISNA(MATCH(4,Engine!$C$2:$C$1369,0)),"",INDEX('Compliance Database'!$K$2:$K$1369,MATCH(4,Engine!$C$2:$C$1369,0))) | L17: =IF(ISNA(MATCH(4,Engine!$C$2:$C$1369,0)),"",INDEX('Compliance Database'!$L$2:$L$1369,MATCH(4,Engine!$C$2:$C$1369,0))) | M17: =IF(ISNA(MATCH(4,Engine!$C$2:$C$1369,0)),"",INDEX('Compliance Database'!$M$2:$M$1369,MATCH(4,Engine!$C$2:$C$1369,0))) | N17: =IF(ISNA(MATCH(4,Engine!$C$2:$C$1369,0)),"",INDEX('Compliance Database'!$N$2:$N$1369,MATCH(4,Engine!$C$2:$C$1369,0))) | O17: =IF(ISNA(MATCH(4,Engine!$C$2:$C$1369,0)),"",HYPERLINK(INDEX('Compliance Database'!$O$2:$O$1369,MATCH(4,Engine!$C$2:$C$1369,0)),"Open PDF"))
A18: =IF(ISNA(MATCH(5,Engine!$C$2:$C$1369,0)),"",INDEX('Compliance Database'!$A$2:$A$1369,MATCH(5,Engine!$C$2:$C$1369,0))) | B18: =IF(ISNA(MATCH(5,Engine!$C$2:$C$1369,0)),"",INDEX('Compliance Database'!$B$2:$B$1369,MATCH(5,Engine!$C$2:$C$1369,0))) | C18: =IF(ISNA(MATCH(5,Engine!$C$2:$C$1369,0)),"",INDEX('Compliance Database'!$C$2:$C$1369,MATCH(5,Engine!$C$2:$C$1369,0))) | D18: =IF(ISNA(MATCH(5,Engine!$C$2:$C$1369,0)),"",INDEX('Compliance Database'!$D$2:$D$1369,MATCH(5,Engine!$C$2:$C$1369,0))) | E18: =IF(ISNA(MATCH(5,Engine!$C$2:$C$1369,0)),"",INDEX('Compliance Database'!$E$2:$E$1369,MATCH(5,Engine!$C$2:$C$1369,0))) | F18: =IF(ISNA(MATCH(5,Engine!$C$2:$C$1369,0)),"",INDEX('Compliance Database'!$F$2:$F$1369,MATCH(5,Engine!$C$2:$C$1369,0))) | G18: =IF(ISNA(MATCH(5,Engine!$C$2:$C$1369,0)),"",INDEX('Compliance Database'!$G$2:$G$1369,MATCH(5,Engine!$C$2:$C$1369,0))) | H18: =IF(ISNA(MATCH(5,Engine!$C$2:$C$1369,0)),"",INDEX('Compliance Database'!$H$2:$H$1369,MATCH(5,Engine!$C$2:$C$1369,0))) | I18: =IF(ISNA(MATCH(5,Engine!$C$2:$C$1369,0)),"",INDEX('Compliance Database'!$I$2:$I$1369,MATCH(5,Engine!$C$2:$C$1369,0))) | J18: =IF(ISNA(MATCH(5,Engine!$C$2:$C$1369,0)),"",INDEX('Compliance Database'!$J$2:$J$1369,MATCH(5,Engine!$C$2:$C$1369,0))) | K18: =IF(ISNA(MATCH(5,Engine!$C$2:$C$1369,0)),"",INDEX('Compliance Database'!$K$2:$K$1369,MATCH(5,Engine!$C$2:$C$1369,0))) | L18: =IF(ISNA(MATCH(5,Engine!$C$2:$C$1369,0)),"",INDEX('Compliance Database'!$L$2:$L$1369,MATCH(5,Engine!$C$2:$C$1369,0))) | M18: =IF(ISNA(MATCH(5,Engine!$C$2:$C$1369,0)),"",INDEX('Compliance Database'!$M$2:$M$1369,MATCH(5,Engine!$C$2:$C$1369,0))) | N18: =IF(ISNA(MATCH(5,Engine!$C$2:$C$1369,0)),"",INDEX('Compliance Database'!$N$2:$N$1369,MATCH(5,Engine!$C$2:$C$1369,0))) | O18: =IF(ISNA(MATCH(5,Engine!$C$2:$C$1369,0)),"",HYPERLINK(INDEX('Compliance Database'!$O$2:$O$1369,MATCH(5,Engine!$C$2:$C$1369,0)),"Open PDF"))
A19: =IF(ISNA(MATCH(6,Engine!$C$2:$C$1369,0)),"",INDEX('Compliance Database'!$A$2:$A$1369,MATCH(6,Engine!$C$2:$C$1369,0))) | B19: =IF(ISNA(MATCH(6,Engine!$C$2:$C$1369,0)),"",INDEX('Compliance Database'!$B$2:$B$1369,MATCH(6,Engine!$C$2:$C$1369,0))) | C19: =IF(ISNA(MATCH(6,Engine!$C$2:$C$1369,0)),"",INDEX('Compliance Database'!$C$2:$C$1369,MATCH(6,Engine!$C$2:$C$1369,0))) | D19: =IF(ISNA(MATCH(6,Engine!$C$2:$C$1369,0)),"",INDEX('Compliance Database'!$D$2:$D$1369,MATCH(6,Engine!$C$2:$C$1369,0))) | E19: =IF(ISNA(MATCH(6,Engine!$C$2:$C$1369,0)),"",INDEX('Compliance Database'!$E$2:$E$1369,MATCH(6,Engine!$C$2:$C$1369,0))) | F19: =IF(ISNA(MATCH(6,Engine!$C$2:$C$1369,0)),"",INDEX('Compliance Database'!$F$2:$F$1369,MATCH(6,Engine!$C$2:$C$1369,0))) | G19: =IF(ISNA(MATCH(6,Engine!$C$2:$C$1369,0)),"",INDEX('Compliance Database'!$G$2:$G$1369,MATCH(6,Engine!$C$2:$C$1369,0))) | H19: =IF(ISNA(MATCH(6,Engine!$C$2:$C$1369,0)),"",INDEX('Compliance Database'!$H$2:$H$1369,MATCH(6,Engine!$C$2:$C$1369,0))) | I19: =IF(ISNA(MATCH(6,Engine!$C$2:$C$1369,0)),"",INDEX('Compliance Database'!$I$2:$I$1369,MATCH(6,Engine!$C$2:$C$1369,0))) | J19: =IF(ISNA(MATCH(6,Engine!$C$2:$C$1369,0)),"",INDEX('Compliance Database'!$J$2:$J$1369,MATCH(6,Engine!$C$2:$C$1369,0))) | K19: =IF(ISNA(MATCH(6,Engine!$C$2:$C$1369,0)),"",INDEX('Compliance Database'!$K$2:$K$1369,MATCH(6,Engine!$C$2:$C$1369,0))) | L19: =IF(ISNA(MATCH(6,Engine!$C$2:$C$1369,0)),"",INDEX('Compliance Database'!$L$2:$L$1369,MATCH(6,Engine!$C$2:$C$1369,0))) | M19: =IF(ISNA(MATCH(6,Engine!$C$2:$C$1369,0)),"",INDEX('Compliance Database'!$M$2:$M$1369,MATCH(6,Engine!$C$2:$C$1369,0))) | N19: =IF(ISNA(MATCH(6,Engine!$C$2:$C$1369,0)),"",INDEX('Compliance Database'!$N$2:$N$1369,MATCH(6,Engine!$C$2:$C$1369,0))) | O19: =IF(ISNA(MATCH(6,Engine!$C$2:$C$1369,0)),"",HYPERLINK(INDEX('Compliance Database'!$O$2:$O$1369,MATCH(6,Engine!$C$2:$C$1369,0)),"Open PDF"))
A20: =IF(ISNA(MATCH(7,Engine!$C$2:$C$1369,0)),"",INDEX('Compliance Database'!$A$2:$A$1369,MATCH(7,Engine!$C$2:$C$1369,0))) | B20: =IF(ISNA(MATCH(7,Engine!$C$2:$C$1369,0)),"",INDEX('Compliance Database'!$B$2:$B$1369,MATCH(7,Engine!$C$2:$C$1369,0))) | C20: =IF(ISNA(MATCH(7,Engine!$C$2:$C$1369,0)),"",INDEX('Compliance Database'!$C$2:$C$1369,MATCH(7,Engine!$C$2:$C$1369,0))) | D20: =IF(ISNA(MATCH(7,Engine!$C$2:$C$1369,0)),"",INDEX('Compliance Database'!$D$2:$D$1369,MATCH(7,Engine!$C$2:$C$1369,0))) | E20: =IF(ISNA(MATCH(7,Engine!$C$2:$C$1369,0)),"",INDEX('Compliance Database'!$E$2:$E$1369,MATCH(7,Engine!$C$2:$C$1369,0))) | F20: =IF(ISNA(MATCH(7,Engine!$C$2:$C$1369,0)),"",INDEX('Compliance Database'!$F$2:$F$1369,MATCH(7,Engine!$C$2:$C$1369,0))) | G20: =IF(ISNA(MATCH(7,Engine!$C$2:$C$1369,0)),"",INDEX('Compliance Database'!$G$2:$G$1369,MATCH(7,Engine!$C$2:$C$1369,0))) | H20: =IF(ISNA(MATCH(7,Engine!$C$2:$C$1369,0)),"",INDEX('Compliance Database'!$H$2:$H$1369,MATCH(7,Engine!$C$2:$C$1369,0))) | I20: =IF(ISNA(MATCH(7,Engine!$C$2:$C$1369,0)),"",INDEX('Compliance Database'!$I$2:$I$1369,MATCH(7,Engine!$C$2:$C$1369,0))) | J20: =IF(ISNA(MATCH(7,Engine!$C$2:$C$1369,0)),"",INDEX('Compliance Database'!$J$2:$J$1369,MATCH(7,Engine!$C$2:$C$1369,0))) | K20: =IF(ISNA(MATCH(7,Engine!$C$2:$C$1369,0)),"",INDEX('Compliance Database'!$K$2:$K$1369,MATCH(7,Engine!$C$2:$C$1369,0))) | L20: =IF(ISNA(MATCH(7,Engine!$C$2:$C$1369,0)),"",INDEX('Compliance Database'!$L$2:$L$1369,MATCH(7,Engine!$C$2:$C$1369,0))) | M20: =IF(ISNA(MATCH(7,Engine!$C$2:$C$1369,0)),"",INDEX('Compliance Database'!$M$2:$M$1369,MATCH(7,Engine!$C$2:$C$1369,0))) | N20: =IF(ISNA(MATCH(7,Engine!$C$2:$C$1369,0)),"",INDEX('Compliance Database'!$N$2:$N$1369,MATCH(7,Engine!$C$2:$C$1369,0))) | O20: =IF(ISNA(MATCH(7,Engine!$C$2:$C$1369,0)),"",HYPERLINK(INDEX('Compliance Database'!$O$2:$O$1369,MATCH(7,Engine!$C$2:$C$1369,0)),"Open PDF"))
A21: =IF(ISNA(MATCH(8,Engine!$C$2:$C$1369,0)),"",INDEX('Compliance Database'!$A$2:$A$1369,MATCH(8,Engine!$C$2:$C$1369,0))) | B21: =IF(ISNA(MATCH(8,Engine!$C$2:$C$1369,0)),"",INDEX('Compliance Database'!$B$2:$B$1369,MATCH(8,Engine!$C$2:$C$1369,0))) | C21: =IF(ISNA(MATCH(8,Engine!$C$2:$C$1369,0)),"",INDEX('Compliance Database'!$C$2:$C$1369,MATCH(8,Engine!$C$2:$C$1369,0))) | D21: =IF(ISNA(MATCH(8,Engine!$C$2:$C$1369,0)),"",INDEX('Compliance Database'!$D$2:$D$1369,MATCH(8,Engine!$C$2:$C$1369,0))) | E21: =IF(ISNA(MATCH(8,Engine!$C$2:$C$1369,0)),"",INDEX('Compliance Database'!$E$2:$E$1369,MATCH(8,Engine!$C$2:$C$1369,0))) | F21: =IF(ISNA(MATCH(8,Engine!$C$2:$C$1369,0)),"",INDEX('Compliance Database'!$F$2:$F$1369,MATCH(8,Engine!$C$2:$C$1369,0))) | G21: =IF(ISNA(MATCH(8,Engine!$C$2:$C$1369,0)),"",INDEX('Compliance Database'!$G$2:$G$1369,MATCH(8,Engine!$C$2:$C$1369,0))) | H21: =IF(ISNA(MATCH(8,Engine!$C$2:$C$1369,0)),"",INDEX('Compliance Database'!$H$2:$H$1369,MATCH(8,Engine!$C$2:$C$1369,0))) | I21: =IF(ISNA(MATCH(8,Engine!$C$2:$C$1369,0)),"",INDEX('Compliance Database'!$I$2:$I$1369,MATCH(8,Engine!$C$2:$C$1369,0))) | J21: =IF(ISNA(MATCH(8,Engine!$C$2:$C$1369,0)),"",INDEX('Compliance Database'!$J$2:$J$1369,MATCH(8,Engine!$C$2:$C$1369,0))) | K21: =IF(ISNA(MATCH(8,Engine!$C$2:$C$1369,0)),"",INDEX('Compliance Database'!$K$2:$K$1369,MATCH(8,Engine!$C$2:$C$1369,0))) | L21: =IF(ISNA(MATCH(8,Engine!$C$2:$C$1369,0)),"",INDEX('Compliance Database'!$L$2:$L$1369,MATCH(8,Engine!$C$2:$C$1369,0))) | M21: =IF(ISNA(MATCH(8,Engine!$C$2:$C$1369,0)),"",INDEX('Compliance Database'!$M$2:$M$1369,MATCH(8,Engine!$C$2:$C$1369,0))) | N21: =IF(ISNA(MATCH(8,Engine!$C$2:$C$1369,0)),"",INDEX('Compliance Database'!$N$2:$N$1369,MATCH(8,Engine!$C$2:$C$1369,0))) | O21: =IF(ISNA(MATCH(8,Engine!$C$2:$C$1369,0)),"",HYPERLINK(INDEX('Compliance Database'!$O$2:$O$1369,MATCH(8,Engine!$C$2:$C$1369,0)),"Open PDF"))
A22: =IF(ISNA(MATCH(9,Engine!$C$2:$C$1369,0)),"",INDEX('Compliance Database'!$A$2:$A$1369,MATCH(9,Engine!$C$2:$C$1369,0))) | B22: =IF(ISNA(MATCH(9,Engine!$C$2:$C$1369,0)),"",INDEX('Compliance Database'!$B$2:$B$1369,MATCH(9,Engine!$C$2:$C$1369,0))) | C22: =IF(ISNA(MATCH(9,Engine!$C$2:$C$1369,0)),"",INDEX('Compliance Database'!$C$2:$C$1369,MATCH(9,Engine!$C$2:$C$1369,0))) | D22: =IF(ISNA(MATCH(9,Engine!$C$2:$C$1369,0)),"",INDEX('Compliance Database'!$D$2:$D$1369,MATCH(9,Engine!$C$2:$C$1369,0))) | E22: =IF(ISNA(MATCH(9,Engine!$C$2:$C$1369,0)),"",INDEX('Compliance Database'!$E$2:$E$1369,MATCH(9,Engine!$C$2:$C$1369,0))) | F22: =IF(ISNA(MATCH(9,Engine!$C$2:$C$1369,0)),"",INDEX('Compliance Database'!$F$2:$F$1369,MATCH(9,Engine!$C$2:$C$1369,0))) | G22: =IF(ISNA(MATCH(9,Engine!$C$2:$C$1369,0)),"",INDEX('Compliance Database'!$G$2:$G$1369,MATCH(9,Engine!$C$2:$C$1369,0))) | H22: =IF(ISNA(MATCH(9,Engine!$C$2:$C$1369,0)),"",INDEX('Compliance Database'!$H$2:$H$1369,MATCH(9,Engine!$C$2:$C$1369,0))) | I22: =IF(ISNA(MATCH(9,Engine!$C$2:$C$1369,0)),"",INDEX('Compliance Database'!$I$2:$I$1369,MATCH(9,Engine!$C$2:$C$1369,0))) | J22: =IF(ISNA(MATCH(9,Engine!$C$2:$C$1369,0)),"",INDEX('Compliance Database'!$J$2:$J$1369,MATCH(9,Engine!$C$2:$C$1369,0))) | K22: =IF(ISNA(MATCH(9,Engine!$C$2:$C$1369,0)),"",INDEX('Compliance Database'!$K$2:$K$1369,MATCH(9,Engine!$C$2:$C$1369,0))) | L22: =IF(ISNA(MATCH(9,Engine!$C$2:$C$1369,0)),"",INDEX('Compliance Database'!$L$2:$L$1369,MATCH(9,Engine!$C$2:$C$1369,0))) | M22: =IF(ISNA(MATCH(9,Engine!$C$2:$C$1369,0)),"",INDEX('Compliance Database'!$M$2:$M$1369,MATCH(9,Engine!$C$2:$C$1369,0))) | N22: =IF(ISNA(MATCH(9,Engine!$C$2:$C$1369,0)),"",INDEX('Compliance Database'!$N$2:$N$1369,MATCH(9,Engine!$C$2:$C$1369,0))) | O22: =IF(ISNA(MATCH(9,Engine!$C$2:$C$1369,0)),"",HYPERLINK(INDEX('Compliance Database'!$O$2:$O$1369,MATCH(9,Engine!$C$2:$C$1369,0)),"Open PDF"))
A23: =IF(ISNA(MATCH(10,Engine!$C$2:$C$1369,0)),"",INDEX('Compliance Database'!$A$2:$A$1369,MATCH(10,Engine!$C$2:$C$1369,0))) | B23: =IF(ISNA(MATCH(10,Engine!$C$2:$C$1369,0)),"",INDEX('Compliance Database'!$B$2:$B$1369,MATCH(10,Engine!$C$2:$C$1369,0))) | C23: =IF(ISNA(MATCH(10,Engine!$C$2:$C$1369,0)),"",INDEX('Compliance Database'!$C$2:$C$1369,MATCH(10,Engine!$C$2:$C$1369,0))) | D23: =IF(ISNA(MATCH(10,Engine!$C$2:$C$1369,0)),"",INDEX('Compliance Database'!$D$2:$D$1369,MATCH(10,Engine!$C$2:$C$1369,0))) | E23: =IF(ISNA(MATCH(10,Engine!$C$2:$C$1369,0)),"",INDEX('Compliance Database'!$E$2:$E$1369,MATCH(10,Engine!$C$2:$C$1369,0))) | F23: =IF(ISNA(MATCH(10,Engine!$C$2:$C$1369,0)),"",INDEX('Compliance Database'!$F$2:$F$1369,MATCH(10,Engine!$C$2:$C$1369,0))) | G23: =IF(ISNA(MATCH(10,Engine!$C$2:$C$1369,0)),"",INDEX('Compliance Database'!$G$2:$G$1369,MATCH(10,Engine!$C$2:$C$1369,0))) | H23: =IF(ISNA(MATCH(10,Engine!$C$2:$C$1369,0)),"",INDEX('Compliance Database'!$H$2:$H$1369,MATCH(10,Engine!$C$2:$C$1369,0))) | I23: =IF(ISNA(MATCH(10,Engine!$C$2:$C$1369,0)),"",INDEX('Compliance Database'!$I$2:$I$1369,MATCH(10,Engine!$C$2:$C$1369,0))) | J23: =IF(ISNA(MATCH(10,Engine!$C$2:$C$1369,0)),"",INDEX('Compliance Database'!$J$2:$J$1369,MATCH(10,Engine!$C$2:$C$1369,0))) | K23: =IF(ISNA(MATCH(10,Engine!$C$2:$C$1369,0)),"",INDEX('Compliance Database'!$K$2:$K$1369,MATCH(10,Engine!$C$2:$C$1369,0))) | L23: =IF(ISNA(MATCH(10,Engine!$C$2:$C$1369,0)),"",INDEX('Compliance Database'!$L$2:$L$1369,MATCH(10,Engine!$C$2:$C$1369,0))) | M23: =IF(ISNA(MATCH(10,Engine!$C$2:$C$1369,0)),"",INDEX('Compliance Database'!$M$2:$M$1369,MATCH(10,Engine!$C$2:$C$1369,0))) | N23: =IF(ISNA(MATCH(10,Engine!$C$2:$C$1369,0)),"",INDEX('Compliance Database'!$N$2:$N$1369,MATCH(10,Engine!$C$2:$C$1369,0))) | O23: =IF(ISNA(MATCH(10,Engine!$C$2:$C$1369,0)),"",HYPERLINK(INDEX('Compliance Database'!$O$2:$O$1369,MATCH(10,Engine!$C$2:$C$1369,0)),"Open PDF"))
A24: =IF(ISNA(MATCH(11,Engine!$C$2:$C$1369,0)),"",INDEX('Compliance Database'!$A$2:$A$1369,MATCH(11,Engine!$C$2:$C$1369,0))) | B24: =IF(ISNA(MATCH(11,Engine!$C$2:$C$1369,0)),"",INDEX('Compliance Database'!$B$2:$B$1369,MATCH(11,Engine!$C$2:$C$1369,0))) | C24: =IF(ISNA(MATCH(11,Engine!$C$2:$C$1369,0)),"",INDEX('Compliance Database'!$C$2:$C$1369,MATCH(11,Engine!$C$2:$C$1369,0))) | D24: =IF(ISNA(MATCH(11,Engine!$C$2:$C$1369,0)),"",INDEX('Compliance Database'!$D$2:$D$1369,MATCH(11,Engine!$C$2:$C$1369,0))) | E24: =IF(ISNA(MATCH(11,Engine!$C$2:$C$1369,0)),"",INDEX('Compliance Database'!$E$2:$E$1369,MATCH(11,Engine!$C$2:$C$1369,0))) | F24: =IF(ISNA(MATCH(11,Engine!$C$2:$C$1369,0)),"",INDEX('Compliance Database'!$F$2:$F$1369,MATCH(11,Engine!$C$2:$C$1369,0))) | G24: =IF(ISNA(MATCH(11,Engine!$C$2:$C$1369,0)),"",INDEX('Compliance Database'!$G$2:$G$1369,MATCH(11,Engine!$C$2:$C$1369,0))) | H24: =IF(ISNA(MATCH(11,Engine!$C$2:$C$1369,0)),"",INDEX('Compliance Database'!$H$2:$H$1369,MATCH(11,Engine!$C$2:$C$1369,0))) | I24: =IF(ISNA(MATCH(11,Engine!$C$2:$C$1369,0)),"",INDEX('Compliance Database'!$I$2:$I$1369,MATCH(11,Engine!$C$2:$C$1369,0))) | J24: =IF(ISNA(MATCH(11,Engine!$C$2:$C$1369,0)),"",INDEX('Compliance Database'!$J$2:$J$1369,MATCH(11,Engine!$C$2:$C$1369,0))) | K24: =IF(ISNA(MATCH(11,Engine!$C$2:$C$1369,0)),"",INDEX('Compliance Database'!$K$2:$K$1369,MATCH(11,Engine!$C$2:$C$1369,0))) | L24: =IF(ISNA(MATCH(11,Engine!$C$2:$C$1369,0)),"",INDEX('Compliance Database'!$L$2:$L$1369,MATCH(11,Engine!$C$2:$C$1369,0))) | M24: =IF(ISNA(MATCH(11,Engine!$C$2:$C$1369,0)),"",INDEX('Compliance Database'!$M$2:$M$1369,MATCH(11,Engine!$C$2:$C$1369,0))) | N24: =IF(ISNA(MATCH(11,Engine!$C$2:$C$1369,0)),"",INDEX('Compliance Database'!$N$2:$N$1369,MATCH(11,Engine!$C$2:$C$1369,0))) | O24: =IF(ISNA(MATCH(11,Engine!$C$2:$C$1369,0)),"",HYPERLINK(INDEX('Compliance Database'!$O$2:$O$1369,MATCH(11,Engine!$C$2:$C$1369,0)),"Open PDF"))
A25: =IF(ISNA(MATCH(12,Engine!$C$2:$C$1369,0)),"",INDEX('Compliance Database'!$A$2:$A$1369,MATCH(12,Engine!$C$2:$C$1369,0))) | B25: =IF(ISNA(MATCH(12,Engine!$C$2:$C$1369,0)),"",INDEX('Compliance Database'!$B$2:$B$1369,MATCH(12,Engine!$C$2:$C$1369,0))) | C25: =IF(ISNA(MATCH(12,Engine!$C$2:$C$1369,0)),"",INDEX('Compliance Database'!$C$2:$C$1369,MATCH(12,Engine!$C$2:$C$1369,0))) | D25: =IF(ISNA(MATCH(12,Engine!$C$2:$C$1369,0)),"",INDEX('Compliance Database'!$D$2:$D$1369,MATCH(12,Engine!$C$2:$C$1369,0))) | E25: =IF(ISNA(MATCH(12,Engine!$C$2:$C$1369,0)),"",INDEX('Compliance Database'!$E$2:$E$1369,MATCH(12,Engine!$C$2:$C$1369,0))) | F25: =IF(ISNA(MATCH(12,Engine!$C$2:$C$1369,0)),"",INDEX('Compliance Database'!$F$2:$F$1369,MATCH(12,Engine!$C$2:$C$1369,0))) | G25: =IF(ISNA(MATCH(12,Engine!$C$2:$C$1369,0)),"",INDEX('Compliance Database'!$G$2:$G$1369,MATCH(12,Engine!$C$2:$C$1369,0))) | H25: =IF(ISNA(MATCH(12,Engine!$C$2:$C$1369,0)),"",INDEX('Compliance Database'!$H$2:$H$1369,MATCH(12,Engine!$C$2:$C$1369,0))) | I25: =IF(ISNA(MATCH(12,Engine!$C$2:$C$1369,0)),"",INDEX('Compliance Database'!$I$2:$I$1369,MATCH(12,Engine!$C$2:$C$1369,0))) | J25: =IF(ISNA(MATCH(12,Engine!$C$2:$C$1369,0)),"",INDEX('Compliance Database'!$J$2:$J$1369,MATCH(12,Engine!$C$2:$C$1369,0))) | K25: =IF(ISNA(MATCH(12,Engine!$C$2:$C$1369,0)),"",INDEX('Compliance Database'!$K$2:$K$1369,MATCH(12,Engine!$C$2:$C$1369,0))) | L25: =IF(ISNA(MATCH(12,Engine!$C$2:$C$1369,0)),"",INDEX('Compliance Database'!$L$2:$L$1369,MATCH(12,Engine!$C$2:$C$1369,0))) | M25: =IF(ISNA(MATCH(12,Engine!$C$2:$C$1369,0)),"",INDEX('Compliance Database'!$M$2:$M$1369,MATCH(12,Engine!$C$2:$C$1369,0))) | N25: =IF(ISNA(MATCH(12,Engine!$C$2:$C$1369,0)),"",INDEX('Compliance Database'!$N$2:$N$1369,MATCH(12,Engine!$C$2:$C$1369,0))) | O25: =IF(ISNA(MATCH(12,Engine!$C$2:$C$1369,0)),"",HYPERLINK(INDEX('Compliance Database'!$O$2:$O$1369,MATCH(12,Engine!$C$2:$C$1369,0)),"Open PDF"))
A26: =IF(ISNA(MATCH(13,Engine!$C$2:$C$1369,0)),"",INDEX('Compliance Database'!$A$2:$A$1369,MATCH(13,Engine!$C$2:$C$1369,0))) | B26: =IF(ISNA(MATCH(13,Engine!$C$2:$C$1369,0)),"",INDEX('Compliance Database'!$B$2:$B$1369,MATCH(13,Engine!$C$2:$C$1369,0))) | C26: =IF(ISNA(MATCH(13,Engine!$C$2:$C$1369,0)),"",INDEX('Compliance Database'!$C$2:$C$1369,MATCH(13,Engine!$C$2:$C$1369,0))) | D26: =IF(ISNA(MATCH(13,Engine!$C$2:$C$1369,0)),"",INDEX('Compliance Database'!$D$2:$D$1369,MATCH(13,Engine!$C$2:$C$1369,0))) | E26: =IF(ISNA(MATCH(13,Engine!$C$2:$C$1369,0)),"",INDEX('Compliance Database'!$E$2:$E$1369,MATCH(13,Engine!$C$2:$C$1369,0))) | F26: =IF(ISNA(MATCH(13,Engine!$C$2:$C$1369,0)),"",INDEX('Compliance Database'!$F$2:$F$1369,MATCH(13,Engine!$C$2:$C$1369,0))) | G26: =IF(ISNA(MATCH(13,Engine!$C$2:$C$1369,0)),"",INDEX('Compliance Database'!$G$2:$G$1369,MATCH(13,Engine!$C$2:$C$1369,0))) | H26: =IF(ISNA(MATCH(13,Engine!$C$2:$C$1369,0)),"",INDEX('Compliance Database'!$H$2:$H$1369,MATCH(13,Engine!$C$2:$C$1369,0))) | I26: =IF(ISNA(MATCH(13,Engine!$C$2:$C$1369,0)),"",INDEX('Compliance Database'!$I$2:$I$1369,MATCH(13,Engine!$C$2:$C$1369,0))) | J26: =IF(ISNA(MATCH(13,Engine!$C$2:$C$1369,0)),"",INDEX('Compliance Database'!$J$2:$J$1369,MATCH(13,Engine!$C$2:$C$1369,0))) | K26: =IF(ISNA(MATCH(13,Engine!$C$2:$C$1369,0)),"",INDEX('Compliance Database'!$K$2:$K$1369,MATCH(13,Engine!$C$2:$C$1369,0))) | L26: =IF(ISNA(MATCH(13,Engine!$C$2:$C$1369,0)),"",INDEX('Compliance Database'!$L$2:$L$1369,MATCH(13,Engine!$C$2:$C$1369,0))) | M26: =IF(ISNA(MATCH(13,Engine!$C$2:$C$1369,0)),"",INDEX('Compliance Database'!$M$2:$M$1369,MATCH(13,Engine!$C$2:$C$1369,0))) | N26: =IF(ISNA(MATCH(13,Engine!$C$2:$C$1369,0)),"",INDEX('Compliance Database'!$N$2:$N$1369,MATCH(13,Engine!$C$2:$C$1369,0))) | O26: =IF(ISNA(MATCH(13,Engine!$C$2:$C$1369,0)),"",HYPERLINK(INDEX('Compliance Database'!$O$2:$O$1369,MATCH(13,Engine!$C$2:$C$1369,0)),"Open PDF"))
A27: =IF(ISNA(MATCH(14,Engine!$C$2:$C$1369,0)),"",INDEX('Compliance Database'!$A$2:$A$1369,MATCH(14,Engine!$C$2:$C$1369,0))) | B27: =IF(ISNA(MATCH(14,Engine!$C$2:$C$1369,0)),"",INDEX('Compliance Database'!$B$2:$B$1369,MATCH(14,Engine!$C$2:$C$1369,0))) | C27: =IF(ISNA(MATCH(14,Engine!$C$2:$C$1369,0)),"",INDEX('Compliance Database'!$C$2:$C$1369,MATCH(14,Engine!$C$2:$C$1369,0))) | D27: =IF(ISNA(MATCH(14,Engine!$C$2:$C$1369,0)),"",INDEX('Compliance Database'!$D$2:$D$1369,MATCH(14,Engine!$C$2:$C$1369,0))) | E27: =IF(ISNA(MATCH(14,Engine!$C$2:$C$1369,0)),"",INDEX('Compliance Database'!$E$2:$E$1369,MATCH(14,Engine!$C$2:$C$1369,0))) | F27: =IF(ISNA(MATCH(14,Engine!$C$2:$C$1369,0)),"",INDEX('Compliance Database'!$F$2:$F$1369,MATCH(14,Engine!$C$2:$C$1369,0))) | G27: =IF(ISNA(MATCH(14,Engine!$C$2:$C$1369,0)),"",INDEX('Compliance Database'!$G$2:$G$1369,MATCH(14,Engine!$C$2:$C$1369,0))) | H27: =IF(ISNA(MATCH(14,Engine!$C$2:$C$1369,0)),"",INDEX('Compliance Database'!$H$2:$H$1369,MATCH(14,Engine!$C$2:$C$1369,0))) | I27: =IF(ISNA(MATCH(14,Engine!$C$2:$C$1369,0)),"",INDEX('Compliance Database'!$I$2:$I$1369,MATCH(14,Engine!$C$2:$C$1369,0))) | J27: =IF(ISNA(MATCH(14,Engine!$C$2:$C$1369,0)),"",INDEX('Compliance Database'!$J$2:$J$1369,MATCH(14,Engine!$C$2:$C$1369,0))) | K27: =IF(ISNA(MATCH(14,Engine!$C$2:$C$1369,0)),"",INDEX('Compliance Database'!$K$2:$K$1369,MATCH(14,Engine!$C$2:$C$1369,0))) | L27: =IF(ISNA(MATCH(14,Engine!$C$2:$C$1369,0)),"",INDEX('Compliance Database'!$L$2:$L$1369,MATCH(14,Engine!$C$2:$C$1369,0))) | M27: =IF(ISNA(MATCH(14,Engine!$C$2:$C$1369,0)),"",INDEX('Compliance Database'!$M$2:$M$1369,MATCH(14,Engine!$C$2:$C$1369,0))) | N27: =IF(ISNA(MATCH(14,Engine!$C$2:$C$1369,0)),"",INDEX('Compliance Database'!$N$2:$N$1369,MATCH(14,Engine!$C$2:$C$1369,0))) | O27: =IF(ISNA(MATCH(14,Engine!$C$2:$C$1369,0)),"",HYPERLINK(INDEX('Compliance Database'!$O$2:$O$1369,MATCH(14,Engine!$C$2:$C$1369,0)),"Open PDF"))
A28: =IF(ISNA(MATCH(15,Engine!$C$2:$C$1369,0)),"",INDEX('Compliance Database'!$A$2:$A$1369,MATCH(15,Engine!$C$2:$C$1369,0))) | B28: =IF(ISNA(MATCH(15,Engine!$C$2:$C$1369,0)),"",INDEX('Compliance Database'!$B$2:$B$1369,MATCH(15,Engine!$C$2:$C$1369,0))) | C28: =IF(ISNA(MATCH(15,Engine!$C$2:$C$1369,0)),"",INDEX('Compliance Database'!$C$2:$C$1369,MATCH(15,Engine!$C$2:$C$1369,0))) | D28: =IF(ISNA(MATCH(15,Engine!$C$2:$C$1369,0)),"",INDEX('Compliance Database'!$D$2:$D$1369,MATCH(15,Engine!$C$2:$C$1369,0))) | E28: =IF(ISNA(MATCH(15,Engine!$C$2:$C$1369,0)),"",INDEX('Compliance Database'!$E$2:$E$1369,MATCH(15,Engine!$C$2:$C$1369,0))) | F28: =IF(ISNA(MATCH(15,Engine!$C$2:$C$1369,0)),"",INDEX('Compliance Database'!$F$2:$F$1369,MATCH(15,Engine!$C$2:$C$1369,0))) | G28: =IF(ISNA(MATCH(15,Engine!$C$2:$C$1369,0)),"",INDEX('Compliance Database'!$G$2:$G$1369,MATCH(15,Engine!$C$2:$C$1369,0))) | H28: =IF(ISNA(MATCH(15,Engine!$C$2:$C$1369,0)),"",INDEX('Compliance Database'!$H$2:$H$1369,MATCH(15,Engine!$C$2:$C$1369,0))) | I28: =IF(ISNA(MATCH(15,Engine!$C$2:$C$1369,0)),"",INDEX('Compliance Database'!$I$2:$I$1369,MATCH(15,Engine!$C$2:$C$1369,0))) | J28: =IF(ISNA(MATCH(15,Engine!$C$2:$C$1369,0)),"",INDEX('Compliance Database'!$J$2:$J$1369,MATCH(15,Engine!$C$2:$C$1369,0))) | K28: =IF(ISNA(MATCH(15,Engine!$C$2:$C$1369,0)),"",INDEX('Compliance Database'!$K$2:$K$1369,MATCH(15,Engine!$C$2:$C$1369,0))) | L28: =IF(ISNA(MATCH(15,Engine!$C$2:$C$1369,0)),"",INDEX('Compliance Database'!$L$2:$L$1369,MATCH(15,Engine!$C$2:$C$1369,0))) | M28: =IF(ISNA(MATCH(15,Engine!$C$2:$C$1369,0)),"",INDEX('Compliance Database'!$M$2:$M$1369,MATCH(15,Engine!$C$2:$C$1369,0))) | N28: =IF(ISNA(MATCH(15,Engine!$C$2:$C$1369,0)),"",INDEX('Compliance Database'!$N$2:$N$1369,MATCH(15,Engine!$C$2:$C$1369,0))) | O28: =IF(ISNA(MATCH(15,Engine!$C$2:$C$1369,0)),"",HYPERLINK(INDEX('Compliance Database'!$O$2:$O$1369,MATCH(15,Engine!$C$2:$C$1369,0)),"Open PDF"))
A29: =IF(ISNA(MATCH(16,Engine!$C$2:$C$1369,0)),"",INDEX('Compliance Database'!$A$2:$A$1369,MATCH(16,Engine!$C$2:$C$1369,0))) | B29: =IF(ISNA(MATCH(16,Engine!$C$2:$C$1369,0)),"",INDEX('Compliance Database'!$B$2:$B$1369,MATCH(16,Engine!$C$2:$C$1369,0))) | C29: =IF(ISNA(MATCH(16,Engine!$C$2:$C$1369,0)),"",INDEX('Compliance Database'!$C$2:$C$1369,MATCH(16,Engine!$C$2:$C$1369,0))) | D29: =IF(ISNA(MATCH(16,Engine!$C$2:$C$1369,0)),"",INDEX('Compliance Database'!$D$2:$D$1369,MATCH(16,Engine!$C$2:$C$1369,0))) | E29: =IF(ISNA(MATCH(16,Engine!$C$2:$C$1369,0)),"",INDEX('Compliance Database'!$E$2:$E$1369,MATCH(16,Engine!$C$2:$C$1369,0))) | F29: =IF(ISNA(MATCH(16,Engine!$C$2:$C$1369,0)),"",INDEX('Compliance Database'!$F$2:$F$1369,MATCH(16,Engine!$C$2:$C$1369,0))) | G29: =IF(ISNA(MATCH(16,Engine!$C$2:$C$1369,0)),"",INDEX('Compliance Database'!$G$2:$G$1369,MATCH(16,Engine!$C$2:$C$1369,0))) | H29: =IF(ISNA(MATCH(16,Engine!$C$2:$C$1369,0)),"",INDEX('Compliance Database'!$H$2:$H$1369,MATCH(16,Engine!$C$2:$C$1369,0))) | I29: =IF(ISNA(MATCH(16,Engine!$C$2:$C$1369,0)),"",INDEX('Compliance Database'!$I$2:$I$1369,MATCH(16,Engine!$C$2:$C$1369,0))) | J29: =IF(ISNA(MATCH(16,Engine!$C$2:$C$1369,0)),"",INDEX('Compliance Database'!$J$2:$J$1369,MATCH(16,Engine!$C$2:$C$1369,0))) | K29: =IF(ISNA(MATCH(16,Engine!$C$2:$C$1369,0)),"",INDEX('Compliance Database'!$K$2:$K$1369,MATCH(16,Engine!$C$2:$C$1369,0))) | L29: =IF(ISNA(MATCH(16,Engine!$C$2:$C$1369,0)),"",INDEX('Compliance Database'!$L$2:$L$1369,MATCH(16,Engine!$C$2:$C$1369,0))) | M29: =IF(ISNA(MATCH(16,Engine!$C$2:$C$1369,0)),"",INDEX('Compliance Database'!$M$2:$M$1369,MATCH(16,Engine!$C$2:$C$1369,0))) | N29: =IF(ISNA(MATCH(16,Engine!$C$2:$C$1369,0)),"",INDEX('Compliance Database'!$N$2:$N$1369,MATCH(16,Engine!$C$2:$C$1369,0))) | O29: =IF(ISNA(MATCH(16,Engine!$C$2:$C$1369,0)),"",HYPERLINK(INDEX('Compliance Database'!$O$2:$O$1369,MATCH(16,Engine!$C$2:$C$1369,0)),"Open PDF"))
A30: =IF(ISNA(MATCH(17,Engine!$C$2:$C$1369,0)),"",INDEX('Compliance Database'!$A$2:$A$1369,MATCH(17,Engine!$C$2:$C$1369,0))) | B30: =IF(ISNA(MATCH(17,Engine!$C$2:$C$1369,0)),"",INDEX('Compliance Database'!$B$2:$B$1369,MATCH(17,Engine!$C$2:$C$1369,0))) | C30: =IF(ISNA(MATCH(17,Engine!$C$2:$C$1369,0)),"",INDEX('Compliance Database'!$C$2:$C$1369,MATCH(17,Engine!$C$2:$C$1369,0))) | D30: =IF(ISNA(MATCH(17,Engine!$C$2:$C$1369,0)),"",INDEX('Compliance Database'!$D$2:$D$1369,MATCH(17,Engine!$C$2:$C$1369,0))) | E30: =IF(ISNA(MATCH(17,Engine!$C$2:$C$1369,0)),"",INDEX('Compliance Database'!$E$2:$E$1369,MATCH(17,Engine!$C$2:$C$1369,0))) | F30: =IF(ISNA(MATCH(17,Engine!$C$2:$C$1369,0)),"",INDEX('Compliance Database'!$F$2:$F$1369,MATCH(17,Engine!$C$2:$C$1369,0))) | G30: =IF(ISNA(MATCH(17,Engine!$C$2:$C$1369,0)),"",INDEX('Compliance Database'!$G$2:$G$1369,MATCH(17,Engine!$C$2:$C$1369,0))) | H30: =IF(ISNA(MATCH(17,Engine!$C$2:$C$1369,0)),"",INDEX('Compliance Database'!$H$2:$H$1369,MATCH(17,Engine!$C$2:$C$1369,0))) | I30: =IF(ISNA(MATCH(17,Engine!$C$2:$C$1369,0)),"",INDEX('Compliance Database'!$I$2:$I$1369,MATCH(17,Engine!$C$2:$C$1369,0))) | J30: =IF(ISNA(MATCH(17,Engine!$C$2:$C$1369,0)),"",INDEX('Compliance Database'!$J$2:$J$1369,MATCH(17,Engine!$C$2:$C$1369,0))) | K30: =IF(ISNA(MATCH(17,Engine!$C$2:$C$1369,0)),"",INDEX('Compliance Database'!$K$2:$K$1369,MATCH(17,Engine!$C$2:$C$1369,0))) | L30: =IF(ISNA(MATCH(17,Engine!$C$2:$C$1369,0)),"",INDEX('Compliance Database'!$L$2:$L$1369,MATCH(17,Engine!$C$2:$C$1369,0))) | M30: =IF(ISNA(MATCH(17,Engine!$C$2:$C$1369,0)),"",INDEX('Compliance Database'!$M$2:$M$1369,MATCH(17,Engine!$C$2:$C$1369,0))) | N30: =IF(ISNA(MATCH(17,Engine!$C$2:$C$1369,0)),"",INDEX('Compliance Database'!$N$2:$N$1369,MATCH(17,Engine!$C$2:$C$1369,0))) | O30: =IF(ISNA(MATCH(17,Engine!$C$2:$C$1369,0)),"",HYPERLINK(INDEX('Compliance Database'!$O$2:$O$1369,MATCH(17,Engine!$C$2:$C$1369,0)),"Open PDF"))
A31: =IF(ISNA(MATCH(18,Engine!$C$2:$C$1369,0)),"",INDEX('Compliance Database'!$A$2:$A$1369,MATCH(18,Engine!$C$2:$C$1369,0))) | B31: =IF(ISNA(MATCH(18,Engine!$C$2:$C$1369,0)),"",INDEX('Compliance Database'!$B$2:$B$1369,MATCH(18,Engine!$C$2:$C$1369,0))) | C31: =IF(ISNA(MATCH(18,Engine!$C$2:$C$1369,0)),"",INDEX('Compliance Database'!$C$2:$C$1369,MATCH(18,Engine!$C$2:$C$1369,0))) | D31: =IF(ISNA(MATCH(18,Engine!$C$2:$C$1369,0)),"",INDEX('Compliance Database'!$D$2:$D$1369,MATCH(18,Engine!$C$2:$C$1369,0))) | E31: =IF(ISNA(MATCH(18,Engine!$C$2:$C$1369,0)),"",INDEX('Compliance Database'!$E$2:$E$1369,MATCH(18,Engine!$C$2:$C$1369,0))) | F31: =IF(ISNA(MATCH(18,Engine!$C$2:$C$1369,0)),"",INDEX('Compliance Database'!$F$2:$F$1369,MATCH(18,Engine!$C$2:$C$1369,0))) | G31: =IF(ISNA(MATCH(18,Engine!$C$2:$C$1369,0)),"",INDEX('Compliance Database'!$G$2:$G$1369,MATCH(18,Engine!$C$2:$C$1369,0))) | H31: =IF(ISNA(MATCH(18,Engine!$C$2:$C$1369,0)),"",INDEX('Compliance Database'!$H$2:$H$1369,MATCH(18,Engine!$C$2:$C$1369,0))) | I31: =IF(ISNA(MATCH(18,Engine!$C$2:$C$1369,0)),"",INDEX('Compliance Database'!$I$2:$I$1369,MATCH(18,Engine!$C$2:$C$1369,0))) | J31: =IF(ISNA(MATCH(18,Engine!$C$2:$C$1369,0)),"",INDEX('Compliance Database'!$J$2:$J$1369,MATCH(18,Engine!$C$2:$C$1369,0))) | K31: =IF(ISNA(MATCH(18,Engine!$C$2:$C$1369,0)),"",INDEX('Compliance Database'!$K$2:$K$1369,MATCH(18,Engine!$C$2:$C$1369,0))) | L31: =IF(ISNA(MATCH(18,Engine!$C$2:$C$1369,0)),"",INDEX('Compliance Database'!$L$2:$L$1369,MATCH(18,Engine!$C$2:$C$1369,0))) | M31: =IF(ISNA(MATCH(18,Engine!$C$2:$C$1369,0)),"",INDEX('Compliance Database'!$M$2:$M$1369,MATCH(18,Engine!$C$2:$C$1369,0))) | N31: =IF(ISNA(MATCH(18,Engine!$C$2:$C$1369,0)),"",INDEX('Compliance Database'!$N$2:$N$1369,MATCH(18,Engine!$C$2:$C$1369,0))) | O31: =IF(ISNA(MATCH(18,Engine!$C$2:$C$1369,0)),"",HYPERLINK(INDEX('Compliance Database'!$O$2:$O$1369,MATCH(18,Engine!$C$2:$C$1369,0)),"Open PDF"))
A32: =IF(ISNA(MATCH(19,Engine!$C$2:$C$1369,0)),"",INDEX('Compliance Database'!$A$2:$A$1369,MATCH(19,Engine!$C$2:$C$1369,0))) | B32: =IF(ISNA(MATCH(19,Engine!$C$2:$C$1369,0)),"",INDEX('Compliance Database'!$B$2:$B$1369,MATCH(19,Engine!$C$2:$C$1369,0))) | C32: =IF(ISNA(MATCH(19,Engine!$C$2:$C$1369,0)),"",INDEX('Compliance Database'!$C$2:$C$1369,MATCH(19,Engine!$C$2:$C$1369,0))) | D32: =IF(ISNA(MATCH(19,Engine!$C$2:$C$1369,0)),"",INDEX('Compliance Database'!$D$2:$D$1369,MATCH(19,Engine!$C$2:$C$1369,0))) | E32: =IF(ISNA(MATCH(19,Engine!$C$2:$C$1369,0)),"",INDEX('Compliance Database'!$E$2:$E$1369,MATCH(19,Engine!$C$2:$C$1369,0))) | F32: =IF(ISNA(MATCH(19,Engine!$C$2:$C$1369,0)),"",INDEX('Compliance Database'!$F$2:$F$1369,MATCH(19,Engine!$C$2:$C$1369,0))) | G32: =IF(ISNA(MATCH(19,Engine!$C$2:$C$1369,0)),"",INDEX('Compliance Database'!$G$2:$G$1369,MATCH(19,Engine!$C$2:$C$1369,0))) | H32: =IF(ISNA(MATCH(19,Engine!$C$2:$C$1369,0)),"",INDEX('Compliance Database'!$H$2:$H$1369,MATCH(19,Engine!$C$2:$C$1369,0))) | I32: =IF(ISNA(MATCH(19,Engine!$C$2:$C$1369,0)),"",INDEX('Compliance Database'!$I$2:$I$1369,MATCH(19,Engine!$C$2:$C$1369,0))) | J32: =IF(ISNA(MATCH(19,Engine!$C$2:$C$1369,0)),"",INDEX('Compliance Database'!$J$2:$J$1369,MATCH(19,Engine!$C$2:$C$1369,0))) | K32: =IF(ISNA(MATCH(19,Engine!$C$2:$C$1369,0)),"",INDEX('Compliance Database'!$K$2:$K$1369,MATCH(19,Engine!$C$2:$C$1369,0))) | L32: =IF(ISNA(MATCH(19,Engine!$C$2:$C$1369,0)),"",INDEX('Compliance Database'!$L$2:$L$1369,MATCH(19,Engine!$C$2:$C$1369,0))) | M32: =IF(ISNA(MATCH(19,Engine!$C$2:$C$1369,0)),"",INDEX('Compliance Database'!$M$2:$M$1369,MATCH(19,Engine!$C$2:$C$1369,0))) | N32: =IF(ISNA(MATCH(19,Engine!$C$2:$C$1369,0)),"",INDEX('Compliance Database'!$N$2:$N$1369,MATCH(19,Engine!$C$2:$C$1369,0))) | O32: =IF(ISNA(MATCH(19,Engine!$C$2:$C$1369,0)),"",HYPERLINK(INDEX('Compliance Database'!$O$2:$O$1369,MATCH(19,Engine!$C$2:$C$1369,0)),"Open PDF"))
A33: =IF(ISNA(MATCH(20,Engine!$C$2:$C$1369,0)),"",INDEX('Compliance Database'!$A$2:$A$1369,MATCH(20,Engine!$C$2:$C$1369,0))) | B33: =IF(ISNA(MATCH(20,Engine!$C$2:$C$1369,0)),"",INDEX('Compliance Database'!$B$2:$B$1369,MATCH(20,Engine!$C$2:$C$1369,0))) | C33: =IF(ISNA(MATCH(20,Engine!$C$2:$C$1369,0)),"",INDEX('Compliance Database'!$C$2:$C$1369,MATCH(20,Engine!$C$2:$C$1369,0))) | D33: =IF(ISNA(MATCH(20,Engine!$C$2:$C$1369,0)),"",INDEX('Compliance Database'!$D$2:$D$1369,MATCH(20,Engine!$C$2:$C$1369,0))) | E33: =IF(ISNA(MATCH(20,Engine!$C$2:$C$1369,0)),"",INDEX('Compliance Database'!$E$2:$E$1369,MATCH(20,Engine!$C$2:$C$1369,0))) | F33: =IF(ISNA(MATCH(20,Engine!$C$2:$C$1369,0)),"",INDEX('Compliance Database'!$F$2:$F$1369,MATCH(20,Engine!$C$2:$C$1369,0))) | G33: =IF(ISNA(MATCH(20,Engine!$C$2:$C$1369,0)),"",INDEX('Compliance Database'!$G$2:$G$1369,MATCH(20,Engine!$C$2:$C$1369,0))) | H33: =IF(ISNA(MATCH(20,Engine!$C$2:$C$1369,0)),"",INDEX('Compliance Database'!$H$2:$H$1369,MATCH(20,Engine!$C$2:$C$1369,0))) | I33: =IF(ISNA(MATCH(20,Engine!$C$2:$C$1369,0)),"",INDEX('Compliance Database'!$I$2:$I$1369,MATCH(20,Engine!$C$2:$C$1369,0))) | J33: =IF(ISNA(MATCH(20,Engine!$C$2:$C$1369,0)),"",INDEX('Compliance Database'!$J$2:$J$1369,MATCH(20,Engine!$C$2:$C$1369,0))) | K33: =IF(ISNA(MATCH(20,Engine!$C$2:$C$1369,0)),"",INDEX('Compliance Database'!$K$2:$K$1369,MATCH(20,Engine!$C$2:$C$1369,0))) | L33: =IF(ISNA(MATCH(20,Engine!$C$2:$C$1369,0)),"",INDEX('Compliance Database'!$L$2:$L$1369,MATCH(20,Engine!$C$2:$C$1369,0))) | M33: =IF(ISNA(MATCH(20,Engine!$C$2:$C$1369,0)),"",INDEX('Compliance Database'!$M$2:$M$1369,MATCH(20,Engine!$C$2:$C$1369,0))) | N33: =IF(ISNA(MATCH(20,Engine!$C$2:$C$1369,0)),"",INDEX('Compliance Database'!$N$2:$N$1369,MATCH(20,Engine!$C$2:$C$1369,0))) | O33: =IF(ISNA(MATCH(20,Engine!$C$2:$C$1369,0)),"",HYPERLINK(INDEX('Compliance Database'!$O$2:$O$1369,MATCH(20,Engine!$C$2:$C$1369,0)),"Open PDF"))
A34: =IF(ISNA(MATCH(21,Engine!$C$2:$C$1369,0)),"",INDEX('Compliance Database'!$A$2:$A$1369,MATCH(21,Engine!$C$2:$C$1369,0))) | B34: =IF(ISNA(MATCH(21,Engine!$C$2:$C$1369,0)),"",INDEX('Compliance Database'!$B$2:$B$1369,MATCH(21,Engine!$C$2:$C$1369,0))) | C34: =IF(ISNA(MATCH(21,Engine!$C$2:$C$1369,0)),"",INDEX('Compliance Database'!$C$2:$C$1369,MATCH(21,Engine!$C$2:$C$1369,0))) | D34: =IF(ISNA(MATCH(21,Engine!$C$2:$C$1369,0)),"",INDEX('Compliance Database'!$D$2:$D$1369,MATCH(21,Engine!$C$2:$C$1369,0))) | E34: =IF(ISNA(MATCH(21,Engine!$C$2:$C$1369,0)),"",INDEX('Compliance Database'!$E$2:$E$1369,MATCH(21,Engine!$C$2:$C$1369,0))) | F34: =IF(ISNA(MATCH(21,Engine!$C$2:$C$1369,0)),"",INDEX('Compliance Database'!$F$2:$F$1369,MATCH(21,Engine!$C$2:$C$1369,0))) | G34: =IF(ISNA(MATCH(21,Engine!$C$2:$C$1369,0)),"",INDEX('Compliance Database'!$G$2:$G$1369,MATCH(21,Engine!$C$2:$C$1369,0))) | H34: =IF(ISNA(MATCH(21,Engine!$C$2:$C$1369,0)),"",INDEX('Compliance Database'!$H$2:$H$1369,MATCH(21,Engine!$C$2:$C$1369,0))) | I34: =IF(ISNA(MATCH(21,Engine!$C$2:$C$1369,0)),"",INDEX('Compliance Database'!$I$2:$I$1369,MATCH(21,Engine!$C$2:$C$1369,0))) | J34: =IF(ISNA(MATCH(21,Engine!$C$2:$C$1369,0)),"",INDEX('Compliance Database'!$J$2:$J$1369,MATCH(21,Engine!$C$2:$C$1369,0))) | K34: =IF(ISNA(MATCH(21,Engine!$C$2:$C$1369,0)),"",INDEX('Compliance Database'!$K$2:$K$1369,MATCH(21,Engine!$C$2:$C$1369,0))) | L34: =IF(ISNA(MATCH(21,Engine!$C$2:$C$1369,0)),"",INDEX('Compliance Database'!$L$2:$L$1369,MATCH(21,Engine!$C$2:$C$1369,0))) | M34: =IF(ISNA(MATCH(21,Engine!$C$2:$C$1369,0)),"",INDEX('Compliance Database'!$M$2:$M$1369,MATCH(21,Engine!$C$2:$C$1369,0))) | N34: =IF(ISNA(MATCH(21,Engine!$C$2:$C$1369,0)),"",INDEX('Compliance Database'!$N$2:$N$1369,MATCH(21,Engine!$C$2:$C$1369,0))) | O34: =IF(ISNA(MATCH(21,Engine!$C$2:$C$1369,0)),"",HYPERLINK(INDEX('Compliance Database'!$O$2:$O$1369,MATCH(21,Engine!$C$2:$C$1369,0)),"Open PDF"))
A35: =IF(ISNA(MATCH(22,Engine!$C$2:$C$1369,0)),"",INDEX('Compliance Database'!$A$2:$A$1369,MATCH(22,Engine!$C$2:$C$1369,0))) | B35: =IF(ISNA(MATCH(22,Engine!$C$2:$C$1369,0)),"",INDEX('Compliance Database'!$B$2:$B$1369,MATCH(22,Engine!$C$2:$C$1369,0))) | C35: =IF(ISNA(MATCH(22,Engine!$C$2:$C$1369,0)),"",INDEX('Compliance Database'!$C$2:$C$1369,MATCH(22,Engine!$C$2:$C$1369,0))) | D35: =IF(ISNA(MATCH(22,Engine!$C$2:$C$1369,0)),"",INDEX('Compliance Database'!$D$2:$D$1369,MATCH(22,Engine!$C$2:$C$1369,0))) | E35: =IF(ISNA(MATCH(22,Engine!$C$2:$C$1369,0)),"",INDEX('Compliance Database'!$E$2:$E$1369,MATCH(22,Engine!$C$2:$C$1369,0))) | F35: =IF(ISNA(MATCH(22,Engine!$C$2:$C$1369,0)),"",INDEX('Compliance Database'!$F$2:$F$1369,MATCH(22,Engine!$C$2:$C$1369,0))) | G35: =IF(ISNA(MATCH(22,Engine!$C$2:$C$1369,0)),"",INDEX('Compliance Database'!$G$2:$G$1369,MATCH(22,Engine!$C$2:$C$1369,0))) | H35: =IF(ISNA(MATCH(22,Engine!$C$2:$C$1369,0)),"",INDEX('Compliance Database'!$H$2:$H$1369,MATCH(22,Engine!$C$2:$C$1369,0))) | I35: =IF(ISNA(MATCH(22,Engine!$C$2:$C$1369,0)),"",INDEX('Compliance Database'!$I$2:$I$1369,MATCH(22,Engine!$C$2:$C$1369,0))) | J35: =IF(ISNA(MATCH(22,Engine!$C$2:$C$1369,0)),"",INDEX('Compliance Database'!$J$2:$J$1369,MATCH(22,Engine!$C$2:$C$1369,0))) | K35: =IF(ISNA(MATCH(22,Engine!$C$2:$C$1369,0)),"",INDEX('Compliance Database'!$K$2:$K$1369,MATCH(22,Engine!$C$2:$C$1369,0))) | L35: =IF(ISNA(MATCH(22,Engine!$C$2:$C$1369,0)),"",INDEX('Compliance Database'!$L$2:$L$1369,MATCH(22,Engine!$C$2:$C$1369,0))) | M35: =IF(ISNA(MATCH(22,Engine!$C$2:$C$1369,0)),"",INDEX('Compliance Database'!$M$2:$M$1369,MATCH(22,Engine!$C$2:$C$1369,0))) | N35: =IF(ISNA(MATCH(22,Engine!$C$2:$C$1369,0)),"",INDEX('Compliance Database'!$N$2:$N$1369,MATCH(22,Engine!$C$2:$C$1369,0))) | O35: =IF(ISNA(MATCH(22,Engine!$C$2:$C$1369,0)),"",HYPERLINK(INDEX('Compliance Database'!$O$2:$O$1369,MATCH(22,Engine!$C$2:$C$1369,0)),"Open PDF"))
A36: =IF(ISNA(MATCH(23,Engine!$C$2:$C$1369,0)),"",INDEX('Compliance Database'!$A$2:$A$1369,MATCH(23,Engine!$C$2:$C$1369,0))) | B36: =IF(ISNA(MATCH(23,Engine!$C$2:$C$1369,0)),"",INDEX('Compliance Database'!$B$2:$B$1369,MATCH(23,Engine!$C$2:$C$1369,0))) | C36: =IF(ISNA(MATCH(23,Engine!$C$2:$C$1369,0)),"",INDEX('Compliance Database'!$C$2:$C$1369,MATCH(23,Engine!$C$2:$C$1369,0))) | D36: =IF(ISNA(MATCH(23,Engine!$C$2:$C$1369,0)),"",INDEX('Compliance Database'!$D$2:$D$1369,MATCH(23,Engine!$C$2:$C$1369,0))) | E36: =IF(ISNA(MATCH(23,Engine!$C$2:$C$1369,0)),"",INDEX('Compliance Database'!$E$2:$E$1369,MATCH(23,Engine!$C$2:$C$1369,0))) | F36: =IF(ISNA(MATCH(23,Engine!$C$2:$C$1369,0)),"",INDEX('Compliance Database'!$F$2:$F$1369,MATCH(23,Engine!$C$2:$C$1369,0))) | G36: =IF(ISNA(MATCH(23,Engine!$C$2:$C$1369,0)),"",INDEX('Compliance Database'!$G$2:$G$1369,MATCH(23,Engine!$C$2:$C$1369,0))) | H36: =IF(ISNA(MATCH(23,Engine!$C$2:$C$1369,0)),"",INDEX('Compliance Database'!$H$2:$H$1369,MATCH(23,Engine!$C$2:$C$1369,0))) | I36: =IF(ISNA(MATCH(23,Engine!$C$2:$C$1369,0)),"",INDEX('Compliance Database'!$I$2:$I$1369,MATCH(23,Engine!$C$2:$C$1369,0))) | J36: =IF(ISNA(MATCH(23,Engine!$C$2:$C$1369,0)),"",INDEX('Compliance Database'!$J$2:$J$1369,MATCH(23,Engine!$C$2:$C$1369,0))) | K36: =IF(ISNA(MATCH(23,Engine!$C$2:$C$1369,0)),"",INDEX('Compliance Database'!$K$2:$K$1369,MATCH(23,Engine!$C$2:$C$1369,0))) | L36: =IF(ISNA(MATCH(23,Engine!$C$2:$C$1369,0)),"",INDEX('Compliance Database'!$L$2:$L$1369,MATCH(23,Engine!$C$2:$C$1369,0))) | M36: =IF(ISNA(MATCH(23,Engine!$C$2:$C$1369,0)),"",INDEX('Compliance Database'!$M$2:$M$1369,MATCH(23,Engine!$C$2:$C$1369,0))) | N36: =IF(ISNA(MATCH(23,Engine!$C$2:$C$1369,0)),"",INDEX('Compliance Database'!$N$2:$N$1369,MATCH(23,Engine!$C$2:$C$1369,0))) | O36: =IF(ISNA(MATCH(23,Engine!$C$2:$C$1369,0)),"",HYPERLINK(INDEX('Compliance Database'!$O$2:$O$1369,MATCH(23,Engine!$C$2:$C$1369,0)),"Open PDF"))
A37: =IF(ISNA(MATCH(24,Engine!$C$2:$C$1369,0)),"",INDEX('Compliance Database'!$A$2:$A$1369,MATCH(24,Engine!$C$2:$C$1369,0))) | B37: =IF(ISNA(MATCH(24,Engine!$C$2:$C$1369,0)),"",INDEX('Compliance Database'!$B$2:$B$1369,MATCH(24,Engine!$C$2:$C$1369,0))) | C37: =IF(ISNA(MATCH(24,Engine!$C$2:$C$1369,0)),"",INDEX('Compliance Database'!$C$2:$C$1369,MATCH(24,Engine!$C$2:$C$1369,0))) | D37: =IF(ISNA(MATCH(24,Engine!$C$2:$C$1369,0)),"",INDEX('Compliance Database'!$D$2:$D$1369,MATCH(24,Engine!$C$2:$C$1369,0))) | E37: =IF(ISNA(MATCH(24,Engine!$C$2:$C$1369,0)),"",INDEX('Compliance Database'!$E$2:$E$1369,MATCH(24,Engine!$C$2:$C$1369,0))) | F37: =IF(ISNA(MATCH(24,Engine!$C$2:$C$1369,0)),"",INDEX('Compliance Database'!$F$2:$F$1369,MATCH(24,Engine!$C$2:$C$1369,0))) | G37: =IF(ISNA(MATCH(24,Engine!$C$2:$C$1369,0)),"",INDEX('Compliance Database'!$G$2:$G$1369,MATCH(24,Engine!$C$2:$C$1369,0))) | H37: =IF(ISNA(MATCH(24,Engine!$C$2:$C$1369,0)),"",INDEX('Compliance Database'!$H$2:$H$1369,MATCH(24,Engine!$C$2:$C$1369,0))) | I37: =IF(ISNA(MATCH(24,Engine!$C$2:$C$1369,0)),"",INDEX('Compliance Database'!$I$2:$I$1369,MATCH(24,Engine!$C$2:$C$1369,0))) | J37: =IF(ISNA(MATCH(24,Engine!$C$2:$C$1369,0)),"",INDEX('Compliance Database'!$J$2:$J$1369,MATCH(24,Engine!$C$2:$C$1369,0))) | K37: =IF(ISNA(MATCH(24,Engine!$C$2:$C$1369,0)),"",INDEX('Compliance Database'!$K$2:$K$1369,MATCH(24,Engine!$C$2:$C$1369,0))) | L37: =IF(ISNA(MATCH(24,Engine!$C$2:$C$1369,0)),"",INDEX('Compliance Database'!$L$2:$L$1369,MATCH(24,Engine!$C$2:$C$1369,0))) | M37: =IF(ISNA(MATCH(24,Engine!$C$2:$C$1369,0)),"",INDEX('Compliance Database'!$M$2:$M$1369,MATCH(24,Engine!$C$2:$C$1369,0))) | N37: =IF(ISNA(MATCH(24,Engine!$C$2:$C$1369,0)),"",INDEX('Compliance Database'!$N$2:$N$1369,MATCH(24,Engine!$C$2:$C$1369,0))) | O37: =IF(ISNA(MATCH(24,Engine!$C$2:$C$1369,0)),"",HYPERLINK(INDEX('Compliance Database'!$O$2:$O$1369,MATCH(24,Engine!$C$2:$C$1369,0)),"Open PDF"))
A38: =IF(ISNA(MATCH(25,Engine!$C$2:$C$1369,0)),"",INDEX('Compliance Database'!$A$2:$A$1369,MATCH(25,Engine!$C$2:$C$1369,0))) | B38: =IF(ISNA(MATCH(25,Engine!$C$2:$C$1369,0)),"",INDEX('Compliance Database'!$B$2:$B$1369,MATCH(25,Engine!$C$2:$C$1369,0))) | C38: =IF(ISNA(MATCH(25,Engine!$C$2:$C$1369,0)),"",INDEX('Compliance Database'!$C$2:$C$1369,MATCH(25,Engine!$C$2:$C$1369,0))) | D38: =IF(ISNA(MATCH(25,Engine!$C$2:$C$1369,0)),"",INDEX('Compliance Database'!$D$2:$D$1369,MATCH(25,Engine!$C$2:$C$1369,0))) | E38: =IF(ISNA(MATCH(25,Engine!$C$2:$C$1369,0)),"",INDEX('Compliance Database'!$E$2:$E$1369,MATCH(25,Engine!$C$2:$C$1369,0))) | F38: =IF(ISNA(MATCH(25,Engine!$C$2:$C$1369,0)),"",INDEX('Compliance Database'!$F$2:$F$1369,MATCH(25,Engine!$C$2:$C$1369,0))) | G38: =IF(ISNA(MATCH(25,Engine!$C$2:$C$1369,0)),"",INDEX('Compliance Database'!$G$2:$G$1369,MATCH(25,Engine!$C$2:$C$1369,0))) | H38: =IF(ISNA(MATCH(25,Engine!$C$2:$C$1369,0)),"",INDEX('Compliance Database'!$H$2:$H$1369,MATCH(25,Engine!$C$2:$C$1369,0))) | I38: =IF(ISNA(MATCH(25,Engine!$C$2:$C$1369,0)),"",INDEX('Compliance Database'!$I$2:$I$1369,MATCH(25,Engine!$C$2:$C$1369,0))) | J38: =IF(ISNA(MATCH(25,Engine!$C$2:$C$1369,0)),"",INDEX('Compliance Database'!$J$2:$J$1369,MATCH(25,Engine!$C$2:$C$1369,0))) | K38: =IF(ISNA(MATCH(25,Engine!$C$2:$C$1369,0)),"",INDEX('Compliance Database'!$K$2:$K$1369,MATCH(25,Engine!$C$2:$C$1369,0))) | L38: =IF(ISNA(MATCH(25,Engine!$C$2:$C$1369,0)),"",INDEX('Compliance Database'!$L$2:$L$1369,MATCH(25,Engine!$C$2:$C$1369,0))) | M38: =IF(ISNA(MATCH(25,Engine!$C$2:$C$1369,0)),"",INDEX('Compliance Database'!$M$2:$M$1369,MATCH(25,Engine!$C$2:$C$1369,0))) | N38: =IF(ISNA(MATCH(25,Engine!$C$2:$C$1369,0)),"",INDEX('Compliance Database'!$N$2:$N$1369,MATCH(25,Engine!$C$2:$C$1369,0))) | O38: =IF(ISNA(MATCH(25,Engine!$C$2:$C$1369,0)),"",HYPERLINK(INDEX('Compliance Database'!$O$2:$O$1369,MATCH(25,Engine!$C$2:$C$1369,0)),"Open PDF"))
A39: =IF(ISNA(MATCH(26,Engine!$C$2:$C$1369,0)),"",INDEX('Compliance Database'!$A$2:$A$1369,MATCH(26,Engine!$C$2:$C$1369,0))) | B39: =IF(ISNA(MATCH(26,Engine!$C$2:$C$1369,0)),"",INDEX('Compliance Database'!$B$2:$B$1369,MATCH(26,Engine!$C$2:$C$1369,0))) | C39: =IF(ISNA(MATCH(26,Engine!$C$2:$C$1369,0)),"",INDEX('Compliance Database'!$C$2:$C$1369,MATCH(26,Engine!$C$2:$C$1369,0))) | D39: =IF(ISNA(MATCH(26,Engine!$C$2:$C$1369,0)),"",INDEX('Compliance Database'!$D$2:$D$1369,MATCH(26,Engine!$C$2:$C$1369,0))) | E39: =IF(ISNA(MATCH(26,Engine!$C$2:$C$1369,0)),"",INDEX('Compliance Database'!$E$2:$E$1369,MATCH(26,Engine!$C$2:$C$1369,0))) | F39: =IF(ISNA(MATCH(26,Engine!$C$2:$C$1369,0)),"",INDEX('Compliance Database'!$F$2:$F$1369,MATCH(26,Engine!$C$2:$C$1369,0))) | G39: =IF(ISNA(MATCH(26,Engine!$C$2:$C$1369,0)),"",INDEX('Compliance Database'!$G$2:$G$1369,MATCH(26,Engine!$C$2:$C$1369,0))) | H39: =IF(ISNA(MATCH(26,Engine!$C$2:$C$1369,0)),"",INDEX('Compliance Database'!$H$2:$H$1369,MATCH(26,Engine!$C$2:$C$1369,0))) | I39: =IF(ISNA(MATCH(26,Engine!$C$2:$C$1369,0)),"",INDEX('Compliance Database'!$I$2:$I$1369,MATCH(26,Engine!$C$2:$C$1369,0))) | J39: =IF(ISNA(MATCH(26,Engine!$C$2:$C$1369,0)),"",INDEX('Compliance Database'!$J$2:$J$1369,MATCH(26,Engine!$C$2:$C$1369,0))) | K39: =IF(ISNA(MATCH(26,Engine!$C$2:$C$1369,0)),"",INDEX('Compliance Database'!$K$2:$K$1369,MATCH(26,Engine!$C$2:$C$1369,0))) | L39: =IF(ISNA(MATCH(26,Engine!$C$2:$C$1369,0)),"",INDEX('Compliance Database'!$L$2:$L$1369,MATCH(26,Engine!$C$2:$C$1369,0))) | M39: =IF(ISNA(MATCH(26,Engine!$C$2:$C$1369,0)),"",INDEX('Compliance Database'!$M$2:$M$1369,MATCH(26,Engine!$C$2:$C$1369,0))) | N39: =IF(ISNA(MATCH(26,Engine!$C$2:$C$1369,0)),"",INDEX('Compliance Database'!$N$2:$N$1369,MATCH(26,Engine!$C$2:$C$1369,0))) | O39: =IF(ISNA(MATCH(26,Engine!$C$2:$C$1369,0)),"",HYPERLINK(INDEX('Compliance Database'!$O$2:$O$1369,MATCH(26,Engine!$C$2:$C$1369,0)),"Open PDF"))
A40: =IF(ISNA(MATCH(27,Engine!$C$2:$C$1369,0)),"",INDEX('Compliance Database'!$A$2:$A$1369,MATCH(27,Engine!$C$2:$C$1369,0))) | B40: =IF(ISNA(MATCH(27,Engine!$C$2:$C$1369,0)),"",INDEX('Compliance Database'!$B$2:$B$1369,MATCH(27,Engine!$C$2:$C$1369,0))) | C40: =IF(ISNA(MATCH(27,Engine!$C$2:$C$1369,0)),"",INDEX('Compliance Database'!$C$2:$C$1369,MATCH(27,Engine!$C$2:$C$1369,0))) | D40: =IF(ISNA(MATCH(27,Engine!$C$2:$C$1369,0)),"",INDEX('Compliance Database'!$D$2:$D$1369,MATCH(27,Engine!$C$2:$C$1369,0))) | E40: =IF(ISNA(MATCH(27,Engine!$C$2:$C$1369,0)),"",INDEX('Compliance Database'!$E$2:$E$1369,MATCH(27,Engine!$C$2:$C$1369,0))) | F40: =IF(ISNA(MATCH(27,Engine!$C$2:$C$1369,0)),"",INDEX('Compliance Database'!$F$2:$F$1369,MATCH(27,Engine!$C$2:$C$1369,0))) | G40: =IF(ISNA(MATCH(27,Engine!$C$2:$C$1369,0)),"",INDEX('Compliance Database'!$G$2:$G$1369,MATCH(27,Engine!$C$2:$C$1369,0))) | H40: =IF(ISNA(MATCH(27,Engine!$C$2:$C$1369,0)),"",INDEX('Compliance Database'!$H$2:$H$1369,MATCH(27,Engine!$C$2:$C$1369,0))) | I40: =IF(ISNA(MATCH(27,Engine!$C$2:$C$1369,0)),"",INDEX('Compliance Database'!$I$2:$I$1369,MATCH(27,Engine!$C$2:$C$1369,0))) | J40: =IF(ISNA(MATCH(27,Engine!$C$2:$C$1369,0)),"",INDEX('Compliance Database'!$J$2:$J$1369,MATCH(27,Engine!$C$2:$C$1369,0))) | K40: =IF(ISNA(MATCH(27,Engine!$C$2:$C$1369,0)),"",INDEX('Compliance Database'!$K$2:$K$1369,MATCH(27,Engine!$C$2:$C$1369,0))) | L40: =IF(ISNA(MATCH(27,Engine!$C$2:$C$1369,0)),"",INDEX('Compliance Database'!$L$2:$L$1369,MATCH(27,Engine!$C$2:$C$1369,0))) | M40: =IF(ISNA(MATCH(27,Engine!$C$2:$C$1369,0)),"",INDEX('Compliance Database'!$M$2:$M$1369,MATCH(27,Engine!$C$2:$C$1369,0))) | N40: =IF(ISNA(MATCH(27,Engine!$C$2:$C$1369,0)),"",INDEX('Compliance Database'!$N$2:$N$1369,MATCH(27,Engine!$C$2:$C$1369,0))) | O40: =IF(ISNA(MATCH(27,Engine!$C$2:$C$1369,0)),"",HYPERLINK(INDEX('Compliance Database'!$O$2:$O$1369,MATCH(27,Engine!$C$2:$C$1369,0)),"Open PDF"))
A41: =IF(ISNA(MATCH(28,Engine!$C$2:$C$1369,0)),"",INDEX('Compliance Database'!$A$2:$A$1369,MATCH(28,Engine!$C$2:$C$1369,0))) | B41: =IF(ISNA(MATCH(28,Engine!$C$2:$C$1369,0)),"",INDEX('Compliance Database'!$B$2:$B$1369,MATCH(28,Engine!$C$2:$C$1369,0))) | C41: =IF(ISNA(MATCH(28,Engine!$C$2:$C$1369,0)),"",INDEX('Compliance Database'!$C$2:$C$1369,MATCH(28,Engine!$C$2:$C$1369,0))) | D41: =IF(ISNA(MATCH(28,Engine!$C$2:$C$1369,0)),"",INDEX('Compliance Database'!$D$2:$D$1369,MATCH(28,Engine!$C$2:$C$1369,0))) | E41: =IF(ISNA(MATCH(28,Engine!$C$2:$C$1369,0)),"",INDEX('Compliance Database'!$E$2:$E$1369,MATCH(28,Engine!$C$2:$C$1369,0))) | F41: =IF(ISNA(MATCH(28,Engine!$C$2:$C$1369,0)),"",INDEX('Compliance Database'!$F$2:$F$1369,MATCH(28,Engine!$C$2:$C$1369,0))) | G41: =IF(ISNA(MATCH(28,Engine!$C$2:$C$1369,0)),"",INDEX('Compliance Database'!$G$2:$G$1369,MATCH(28,Engine!$C$2:$C$1369,0))) | H41: =IF(ISNA(MATCH(28,Engine!$C$2:$C$1369,0)),"",INDEX('Compliance Database'!$H$2:$H$1369,MATCH(28,Engine!$C$2:$C$1369,0))) | I41: =IF(ISNA(MATCH(28,Engine!$C$2:$C$1369,0)),"",INDEX('Compliance Database'!$I$2:$I$1369,MATCH(28,Engine!$C$2:$C$1369,0))) | J41: =IF(ISNA(MATCH(28,Engine!$C$2:$C$1369,0)),"",INDEX('Compliance Database'!$J$2:$J$1369,MATCH(28,Engine!$C$2:$C$1369,0))) | K41: =IF(ISNA(MATCH(28,Engine!$C$2:$C$1369,0)),"",INDEX('Compliance Database'!$K$2:$K$1369,MATCH(28,Engine!$C$2:$C$1369,0))) | L41: =IF(ISNA(MATCH(28,Engine!$C$2:$C$1369,0)),"",INDEX('Compliance Database'!$L$2:$L$1369,MATCH(28,Engine!$C$2:$C$1369,0))) | M41: =IF(ISNA(MATCH(28,Engine!$C$2:$C$1369,0)),"",INDEX('Compliance Database'!$M$2:$M$1369,MATCH(28,Engine!$C$2:$C$1369,0))) | N41: =IF(ISNA(MATCH(28,Engine!$C$2:$C$1369,0)),"",INDEX('Compliance Database'!$N$2:$N$1369,MATCH(28,Engine!$C$2:$C$1369,0))) | O41: =IF(ISNA(MATCH(28,Engine!$C$2:$C$1369,0)),"",HYPERLINK(INDEX('Compliance Database'!$O$2:$O$1369,MATCH(28,Engine!$C$2:$C$1369,0)),"Open PDF"))
A42: =IF(ISNA(MATCH(29,Engine!$C$2:$C$1369,0)),"",INDEX('Compliance Database'!$A$2:$A$1369,MATCH(29,Engine!$C$2:$C$1369,0))) | B42: =IF(ISNA(MATCH(29,Engine!$C$2:$C$1369,0)),"",INDEX('Compliance Database'!$B$2:$B$1369,MATCH(29,Engine!$C$2:$C$1369,0))) | C42: =IF(ISNA(MATCH(29,Engine!$C$2:$C$1369,0)),"",INDEX('Compliance Database'!$C$2:$C$1369,MATCH(29,Engine!$C$2:$C$1369,0))) | D42: =IF(ISNA(MATCH(29,Engine!$C$2:$C$1369,0)),"",INDEX('Compliance Database'!$D$2:$D$1369,MATCH(29,Engine!$C$2:$C$1369,0))) | E42: =IF(ISNA(MATCH(29,Engine!$C$2:$C$1369,0)),"",INDEX('Compliance Database'!$E$2:$E$1369,MATCH(29,Engine!$C$2:$C$1369,0))) | F42: =IF(ISNA(MATCH(29,Engine!$C$2:$C$1369,0)),"",INDEX('Compliance Database'!$F$2:$F$1369,MATCH(29,Engine!$C$2:$C$1369,0))) | G42: =IF(ISNA(MATCH(29,Engine!$C$2:$C$1369,0)),"",INDEX('Compliance Database'!$G$2:$G$1369,MATCH(29,Engine!$C$2:$C$1369,0))) | H42: =IF(ISNA(MATCH(29,Engine!$C$2:$C$1369,0)),"",INDEX('Compliance Database'!$H$2:$H$1369,MATCH(29,Engine!$C$2:$C$1369,0))) | I42: =IF(ISNA(MATCH(29,Engine!$C$2:$C$1369,0)),"",INDEX('Compliance Database'!$I$2:$I$1369,MATCH(29,Engine!$C$2:$C$1369,0))) | J42: =IF(ISNA(MATCH(29,Engine!$C$2:$C$1369,0)),"",INDEX('Compliance Database'!$J$2:$J$1369,MATCH(29,Engine!$C$2:$C$1369,0))) | K42: =IF(ISNA(MATCH(29,Engine!$C$2:$C$1369,0)),"",INDEX('Compliance Database'!$K$2:$K$1369,MATCH(29,Engine!$C$2:$C$1369,0))) | L42: =IF(ISNA(MATCH(29,Engine!$C$2:$C$1369,0)),"",INDEX('Compliance Database'!$L$2:$L$1369,MATCH(29,Engine!$C$2:$C$1369,0))) | M42: =IF(ISNA(MATCH(29,Engine!$C$2:$C$1369,0)),"",INDEX('Compliance Database'!$M$2:$M$1369,MATCH(29,Engine!$C$2:$C$1369,0))) | N42: =IF(ISNA(MATCH(29,Engine!$C$2:$C$1369,0)),"",INDEX('Compliance Database'!$N$2:$N$1369,MATCH(29,Engine!$C$2:$C$1369,0))) | O42: =IF(ISNA(MATCH(29,Engine!$C$2:$C$1369,0)),"",HYPERLINK(INDEX('Compliance Database'!$O$2:$O$1369,MATCH(29,Engine!$C$2:$C$1369,0)),"Open PDF"))
A43: =IF(ISNA(MATCH(30,Engine!$C$2:$C$1369,0)),"",INDEX('Compliance Database'!$A$2:$A$1369,MATCH(30,Engine!$C$2:$C$1369,0))) | B43: =IF(ISNA(MATCH(30,Engine!$C$2:$C$1369,0)),"",INDEX('Compliance Database'!$B$2:$B$1369,MATCH(30,Engine!$C$2:$C$1369,0))) | C43: =IF(ISNA(MATCH(30,Engine!$C$2:$C$1369,0)),"",INDEX('Compliance Database'!$C$2:$C$1369,MATCH(30,Engine!$C$2:$C$1369,0))) | D43: =IF(ISNA(MATCH(30,Engine!$C$2:$C$1369,0)),"",INDEX('Compliance Database'!$D$2:$D$1369,MATCH(30,Engine!$C$2:$C$1369,0))) | E43: =IF(ISNA(MATCH(30,Engine!$C$2:$C$1369,0)),"",INDEX('Compliance Database'!$E$2:$E$1369,MATCH(30,Engine!$C$2:$C$1369,0))) | F43: =IF(ISNA(MATCH(30,Engine!$C$2:$C$1369,0)),"",INDEX('Compliance Database'!$F$2:$F$1369,MATCH(30,Engine!$C$2:$C$1369,0))) | G43: =IF(ISNA(MATCH(30,Engine!$C$2:$C$1369,0)),"",INDEX('Compliance Database'!$G$2:$G$1369,MATCH(30,Engine!$C$2:$C$1369,0))) | H43: =IF(ISNA(MATCH(30,Engine!$C$2:$C$1369,0)),"",INDEX('Compliance Database'!$H$2:$H$1369,MATCH(30,Engine!$C$2:$C$1369,0))) | I43: =IF(ISNA(MATCH(30,Engine!$C$2:$C$1369,0)),"",INDEX('Compliance Database'!$I$2:$I$1369,MATCH(30,Engine!$C$2:$C$1369,0))) | J43: =IF(ISNA(MATCH(30,Engine!$C$2:$C$1369,0)),"",INDEX('Compliance Database'!$J$2:$J$1369,MATCH(30,Engine!$C$2:$C$1369,0))) | K43: =IF(ISNA(MATCH(30,Engine!$C$2:$C$1369,0)),"",INDEX('Compliance Database'!$K$2:$K$1369,MATCH(30,Engine!$C$2:$C$1369,0))) | L43: =IF(ISNA(MATCH(30,Engine!$C$2:$C$1369,0)),"",INDEX('Compliance Database'!$L$2:$L$1369,MATCH(30,Engine!$C$2:$C$1369,0))) | M43: =IF(ISNA(MATCH(30,Engine!$C$2:$C$1369,0)),"",INDEX('Compliance Database'!$M$2:$M$1369,MATCH(30,Engine!$C$2:$C$1369,0))) | N43: =IF(ISNA(MATCH(30,Engine!$C$2:$C$1369,0)),"",INDEX('Compliance Database'!$N$2:$N$1369,MATCH(30,Engine!$C$2:$C$1369,0))) | O43: =IF(ISNA(MATCH(30,Engine!$C$2:$C$1369,0)),"",HYPERLINK(INDEX('Compliance Database'!$O$2:$O$1369,MATCH(30,Engine!$C$2:$C$1369,0)),"Open PDF"))
...

Sheet Data Transfer
A1: Cross-Border Data Transfer
A3: Pick the two countries involved in the transfer. Every relevant act/section from either country is listed below; add a keyword to narrow it.
A4: Country A (from) | B4: Australia
A5: Country B (to) | B5: GDPR
A6: Keyword (free text)
A8: Matching sections (of 1368 total): | C8: ='Transfer Engine'!$D$1
A9: Country | B9: Act | C9: Section | D9: Heading | E9: Pages | F9: Financial Relevance | G9: Confidence | H9: Topics | I9: Data Types | J9: Authority | K9: Summary | L9: DTIA Summary | M9: Requirements | N9: Source Quote | O9: Source
